Workbook

Sheet 使い方
A1: MTG要素カタログ
A2: 自作カードゲームに取り込めそうなMTGの要素を、カードタイプからキーワード、デジタル専用メカニズム、定番のデザイン手法まで一覧にしたもの。
A4: 入力欄（薄い黄色）
A5: 採用検討：◎ 採用確定 / ○ 採用候補 / △ アレンジすれば使える / × 不採用。プルダウンから選ぶと集計シートに反映される
A6: メモ：ポイントコスト案や自分のカード名など自由記入。例）飛行 → 採用検討 ○、メモ「貫通 +2pt。ブロック値無視」
A8: 導入しやすさの基準
A9: 高：フラグや数値1つで実装できる（例：速攻、絆魂）
A10: 中：新しいゾーン・状態管理・追加UIが要る（例：墓地から唱える、カウンター管理）
A11: 低：割り込み・スタック・複雑なタイミング処理など大掛かり（例：打ち消し、瞬速の応酬）
A13: 列の見方
A14: 大分類：カードタイプ、キーワード能力、キーワード処理、能力語、デジタル専用メカニズムなど。総合ルール上の区分に準拠
A15: 機能タグ：ゲーム上の役割（攻撃、除去、ドロー・手札、墓地利用など）。デッキの役割設計やカードの並べ替えに使う
... A22: 2026年10月時点で確認できた範囲。新セットで追加された要素は今後増える

Sheet 全要素一覧
A1: No | B1: 大分類 | C1: 機能タグ | D1: 名称（日本語） | E1: 名称（英語） | F1: 総合ルール | G1: MTGでの効果 | H1: 初出 | I1: 自作ゲームへの応用案 | J1: 導入しやすさ | K1: 前提システム | L1: 採用検討 | M1: メモ
A2: 1 | B2: カードタイプ | C2: ルール基盤 | D2: アーティファクト | E2: Artifact | F2: 301 | G2: 無色のものが多い人工物のパーマネント。色を問わず採用でき、装備品や機体などのサブタイプで役割が広がる。 | H2: アルファ (1993) | I2: どのデッキにも入る無属性の装置カード枠として実装する。属性制限を外す代わりにポイント単価を属性カードより高めに設定すると、汎用性と強さの釣り合いが取れる。 | J2: 高 | K2: 永続カード枠 | L2: × | M2: 色が無いので全カードが既に無色。既存：全カード
A3: 2 | B3: カードタイプ | C3: 攻撃 | D3: バトル | E3: Battle | F3: 310 | G3: 守備カウンターで耐久を表すパーマネント。対戦相手が守る側となり、攻撃して守備値を0にすると多くは裏面に変身して報酬になる。 | H3: 機械兵団の進軍 (2023) | I3: 相手側に攻略目標を置くカード。耐久を削り切ると裏面の強力な効果が手に入る形にすると、攻撃を本体と目標のどちらに振るかの判断が生まれる。耐久と報酬からポイントを逆算する。 | J3: 中 | K3: 耐久値・攻撃先選択 | L3: △ | M3: 相手の場に攻撃しない『砦』モンスターを置き、倒すと相手が報酬を得る形なら可。裏面・変身は重い
A4: 3 | B4: カードタイプ | C4: 攻撃 | D4: クリーチャー | E4: Creature | F4: 302 | G4: パワーとタフネスを持ち、攻撃とブロックを担う主力のパーマネント。出たターンは召喚酔いで攻撃できない。 | H4: アルファ (1993) | I4: 場に残って毎ターン働く召喚ユニット。攻撃値と耐久値をポイント1点あたりの換算表で決めると予算管理しやすい。StS型の本体戦闘と並立させるなら、ユニットは自動攻撃にすると操作が軽い。 | J4: 中 | K4: 盤面・ユニット管理 | L4: × | M4: 既存：モンスター
A5: 4 | B5: カードタイプ | C5: 強化 | D5: エンチャント | E5: Enchantment | F5: 303 | G5: 場に残り続けて継続的な効果を与える魔法のパーマネント。オーラや英雄譚など多様なサブタイプを持つ。 | H5: アルファ (1993) | I5: StSのパワーカードに相当する永続効果枠。一度使えば戦闘中ずっと効果が続く。効果量×想定持続ターン数でポイントを見積もり、除去手段の有無で補正する。 | J5: 高 | K5: 永続効果枠 | L5: × | M5: 既存：パワー
A6: 5 | B6: カードタイプ | C6: 妨害 | D6: インスタント | E6: Instant | F6: 304 | G6: 優先権があればいつでも唱えられる使い切りの呪文。相手の行動への対応や戦闘中の奇襲に使う。 | H6: アルファ (1993) | I6: 相手ターン中に使える割り込みカード。オンラインでは制限時間付きの応答待ちが要る。初期実装は「相手の攻撃時に自動で発動する罠」として予約型にすると処理が軽い。 | J6: 低 | K6: 割り込みタイミング | L6: △ | M6: 割り込み不可。予約型の『罠』（相手が攻撃したら発動）なら既存：反撃の拡張として可
A7: 6 | B7: カードタイプ | C7: デッキ構築 | D7: 同族 | E7: Kindred | F7: 308 | G7: 他のカード・タイプと組み合わさり、そのカードにクリーチャー・タイプを持たせるカード・タイプ。旧称は部族で2024年に改名。 | H7: 未来予知 (2007) | I7: スキルや装置カードに種族タグを付ける仕組み。ドラゴン・タグ付きのスキルがドラゴン強化の恩恵を受けるようにすれば種族デッキの幅が広がる。タグ付与自体に少額のポイントを課す。 | J7: 高 | K7: タグ・種族システム | L7: △ | M7: 種族タグをスキルにも付ける案。No.53の種族タグに統合して検討
A8: 7 | B8: カードタイプ | C8: コスト・リソース | D8: 土地 | E8: Land | F8: 305 | G8: マナを生む基盤のパーマネント。唱えずにプレイし、原則1ターンに1枚まで戦場に出せる。 | H8: アルファ (1993) | I8: エネルギー上限を恒久的に伸ばす資源カードとして移植できる。1ターン1枚の制限を付け、資源と通常カードの比率をデッキ構築の要素にする。資源事故対策にドローと選べる2択カードも用意する。 | J8: 中 | K8: マナ/エネルギー | L8: × | M8: 土地・マナ前提。エナジーは自動成長で既存
A9: 8 | B9: カードタイプ | C9: 反復・再利用 | D9: プレインズウォーカー | E9: Planeswalker | F9: 306 | G9: 忠誠カウンターを増減させて1ターンに1回能力を使う味方の魔法使い。攻撃されると忠誠度を失う。 | H9: ローウィン (2007) | I9: 場に置くサブ司令塔カード。耐久値と能力の使用リソースを兼ね、毎ターン能力を1つ選んで使う。相手は本体とこのカードのどちらを狙うか選べる。能力数と初期値でポイントを算出する。 | J9: 中 | K9: 盤面・攻撃先選択 | L9: △ | M9: 重い。パワーに『ターン開始時』効果を持たせる既存の形で代用可
A10: 9 | B10: カードタイプ | C10: ルール基盤 | D10: ソーサリー | E10: Sorcery | F10: 307 | G10: 自分のメイン・フェイズでスタックが空のときだけ唱えられる使い切りの呪文。インスタントより強い効果を持ちやすい。 | H10: アルファ (1993) | I10: StSの通常のアタック・スキルカードがこれに当たる。自ターン専用である代わりに、割り込み可能なカードより同じポイントで効果量を1〜2割増やすとタイミングの価値差を表現できる。 | J10: 高 | K10: なし | L10: × | M10: 既存：全カードが自ターン専用
A11: 10 | B11: カードタイプ | C11: 反復・再利用 | D11: ダンジョン | E11: Dungeon | F11: 309 | G11: ゲームの外から統率領域に置き、探索するたび部屋を1つ進んで部屋能力を得る定形外カード。最奥に着くと踏破となる。 | H11: フォーゴトン・レルム探訪 (2021) | I11: 分岐ルート付きの進行ボードを盤面外に用意し、特定カードで1マス進むたび報酬を得る。踏破回数を参照するカードも作れる。各マスの報酬価値を合算して進行効果のポイントを決める。 | J11: 中 | K11: 進行トラック・UI | L11: × | M11: 進行ボードのUIが重く、面白さに対して実装過大
A12: 11 | B12: カードタイプ | C12: 多人数・交流 | D12: 次元 | E12: Plane | F12: 311 | G12: プレインチェイス戦で使う大判カード。全員に影響する環境効果を持ち、次元ダイスの出目で別の次元へ移る。 | H12: プレインチェイス (2009) | I12: 対戦ごとに無作為に決まるフィールド効果として導入する。全員共通のルール変化をダイスで切り替えれば、オンライン対戦の展開が毎回変わる。カードのポイントには含めない環境枠として扱う。 | J12: 中 | K12: 共有フィールド枠 | L12: △ | M12: 対戦ごとのランダムなフィールド効果（オプション）なら可。カード要素ではない
A13: 12 | B13: カードタイプ | C13: 多人数・交流 | D13: 現象 | E13: Phenomenon | F13: 312 | G13: 次元デッキに混ざる一度きりのイベント・カード。公開されると全体に作用する効果を起こし、すぐ次へ移る。 | H13: プレインチェイス2012 (2012) | I13: フィールド効果の山に混ぜる突発イベント。めくれた瞬間に全員へ1回だけ作用する（全員1枚引くなど）。デジタルなので演出付きで出せ、対戦のマンネリ防止に役立つ。 | J13: 中 | K13: 共有フィールド枠 | L13: × | M13: 共有の次元デッキ・多人数前提
... A25: 24 | B25: サブタイプ | C25: 成長・カウンター | D25: 宇宙船 | E25: Spacecraft | F25: 721 | G25: 配備で他のクリーチャーのパワー分の蓄積カウンターを溜め、規定数を超えると飛行を持つクリーチャーなどになるアーティファクト。 | H25: 久遠の終端 (2025) | I25: 他ユニットの攻撃力を燃料として注ぎ込み、閾値ごとに能力が開放される成長型カード。進捗バーで可視化でき、段階数と最終形の強さでポイントを配分する。 | J25: 中 | K25: カウンター・閾値 | L25: × | M25: 蓄積カウンター＋他ユニットのタップ前提で重い
A26: 25 | B26: サブタイプ | C26: 反復・再利用 | D26: からくり | E26: Contraption | G26: アン・セット専用。別デッキから組み立てて3つの起動輪に置き、毎ターン回る発動！カウンターと一致した輪のものを発動する。 | H26: Unstable (2017) | I26: 本デッキとは別の小デッキから出る装置を3レーンに置き、ターンごとに順番にレーンが起動する仕組み。周期的な効果の可視化はデジタル向き。起動周期を考え、効果量の3分の1程度で評価する。 | J26: 中 | K26: 別デッキ・レーン管理 | L26: × | M26: アン・セット専用・別デッキ前提
A27: 26 | B27: サブタイプ | C27: その他 | D27: アトラクション | E27: Attraction | F27: 717 | G27: 専用のアトラクション・デッキから開いて戦場に出し、毎ターンのダイスの出目が点灯している数字と一致すると効果が出る。 | H27: Unfinity (2022) | I27: 別デッキから出る施設カードに当たり目を設定し、毎ターン自動ダイスで当たれば発動する。当たり目の数で期待値が決まるので、ポイントは効果量×当たり確率で計算できる。 | J27: 中 | K27: 別デッキ・乱数 | L27: × | M27: 別デッキ・ダイス前提
A28: 27 | B28: サブタイプ | C28: ドロー・手札 | D28: 本 | E28: Book | F28: 205.3g | G28: ストリクスヘイヴンの秘密で新設されたアーティファクト・タイプ。固有ルールはなく、ドロー能力を持つものが多い。 | H28: ストリクスヘイヴンの秘密 (2026) | I28: ドロー系の装置に付けるタグ。本の枚数を数えるカードと組めばテーマデッキの軸になる。タグ自体は無料とし、参照する側のカードにポイントを持たせる。 | J28: 高 | K28: タグシステム | L28: × | M28: 効果の無いタグのみ
A29: 28 | B29: サブタイプ | C29: 条件ボーナス | D29: ボブルヘッド | E29: Bobblehead | F29: 205.3g | G29: Fallout統率者デッキで登場したアーティファクト・タイプ。主にマナを出し、ボブルヘッドの数を数えるカードで強くなる。 | H29: Fallout (2024) | I29: 小型の収集品カードを集めるほど効果が伸びるコレクション系タグ。1枚では弱く、所持数を参照するカードで化ける。数を数える効果のポイント係数を別に定めておく。 | J29: 高 | K29: タグシステム | L29: × | M29: マナ・タグ前提
A30: 29 | B30: サブタイプ | C30: 条件ボーナス | D30: インフィニティ | E30: Infinity | F30: 205.3g | G30: インフィニティ・ストーンを表すアーティファクト・タイプ。伝説の破壊不能な装置で、装着すると強力な∞能力が働く。 | H30: マーベル スパイダーマン (2025) | I30: 一定の手順で装着すると隠し能力が開放される特別枠のカード。最高レアリティ専用の演出として使い、開放前後の効果を別々にポイント化する。 | J30: 中 | K30: 状態フラグ | L30: × | M30: 装着手順の特殊枠。重い
A31: 30 | B31: サブタイプ | C31: 強化 | D31: オーラ | E31: Aura | F31: 303.4 | G31: パーマネントやプレイヤーにつけて効果を与えるエンチャント。つけ先がなくなると墓地へ置かれる。 | H31: アルファ (1993) | I31: 敵味方どちらにも貼れる付与カード。味方の強化にも相手の弱体化にも使える。つけ先が倒れると一緒に消えるリスクがあるため、装備型よりポイントを安くする。 | J31: 中 | K31: 装着管理 | L31: × | M31: 既存：攻撃力アップ／弱化／守備力アップ（永続付与）
A32: 31 | B32: サブタイプ | C32: 妨害 | D32: 呪い | E32: Curse | F32: 205.3h | G32: プレイヤーにつけるオーラのサブタイプ。対戦相手に貼り付いて継続的な不利益を与える。 | H32: イニストラード (2011) | I32: ユーザーのゲームの呪いカードと相性が良い。山札に混ぜる呪いとは別に、相手本体に貼り付いて毎ターン不利益を与える呪縛タイプを作り、解除手段もセットで用意する。 | J32: 高 | K32: 状態異常枠 | L32: ◎ | M32: 【今回実装：呪縛】今回実装 効果『呪縛』doom：相手に減らない継続ダメージ（相手のターン開始時。浄化で消える）
A33: 32 | B33: サブタイプ | C33: デッキ構築 | D33: 背景 | E33: Background | F33: 205.3h | G33: 伝説のエンチャントのサブタイプ。背景選択を持つ統率者と組んで2枚目の統率者になり、統率者を強化する。 | H33: 統率者レジェンズ：バルダーズ・ゲートの戦い (2022) | I33: リーダーカードと組み合わせる出自カード。リーダーと出自の2枚選択制にすると組み合わせで戦い方が変わる。出自は控えめな常時効果に限定し、ポイント上限を設ける。 | J33: 高 | K33: キャラ選択 | L33: × | M33: 統率者前提
A34: 33 | B34: サブタイプ | C34: 条件ボーナス | D34: 祭殿 | E34: Shrine | F34: 205.3h | G34: 祭殿の数を参照して効果が大きくなるエンチャント。神河物語で登場し、後に伝説の祭殿サイクルが作られた。 | H34: 神河物語 (2004) | I34: 同じタグのカードを並べるほど1枚ごとの効果が伸びる仕組み。3枚並ぶと効果が数倍になるため、1枚目単体は弱く設定してポイントを抑える。 | J34: 高 | K34: タグ参照 | L34: ◎ | M34: 【今回実装：自分のパワーが2つ以上】今回実装 条件『自分のパワーが2つ以上』twoPowers
A35: 34 | B35: サブタイプ | C35: 強化 | D35: カルトーシュ | E35: Cartouche | F35: 205.3h | G35: アモンケットのオーラのサブタイプ。自分のクリーチャーにつけて強化し、試練などカルトーシュを参照する能力を誘発させる。 | H35: アモンケット (2017) | I35: 付与カードを貼るたびに別のカードが誘発する連鎖の起点となるタグ。カルトーシュ型の付与で手札に戻る報酬を用意すると、付与を軸にしたデッキが組める。 | J35: 高 | K35: 装着・誘発 | L35: × | M35: オーラ・タグ誘発前提
A36: 35 | B36: サブタイプ | C36: 強化 | D36: ルーン | E36: Rune | F36: 205.3h | G36: カルドハイムのオーラのサブタイプ。パーマネントにつき、出たときにカードを1枚引く。装備品につけると装備先に能力を与える。 | H36: カルドハイム (2021) | I36: ユニットにも装備にも貼れる付与で、貼った時点で1枚引ける。損をしにくいのでポイント単価は通常の付与よりやや高めにする。 | J36: 高 | K36: 装着管理 | L36: × | M36: 既存：攻撃力アップ＋ドローの組み合わせで作れる
A37: 36 | B37: サブタイプ | C37: 成長・カウンター | D37: プラン | E37: Plan | F37: 205.3h | G37: 条件を満たすたびにプラン・カウンターが置かれ、規定数に達すると生け贄に捧げて大きな効果を起こすエンチャント。 | H37: マーベル スーパー・ヒーローズ (2026) | I37: 悪役の陰謀カード。条件達成でゲージが溜まり、満タンで強力な効果が発動する。相手から見えるゲージが阻止の駆け引きを生む。段階数と最終効果でポイントを算出する。 | J37: 高 | K37: カウンター・閾値 | L37: △ | M37: ゲージ付きパワー。#154 蓄積カウンターと同じ仕組みで後で
A38: 37 | B38: サブタイプ | C38: コスト・リソース | D38: 基本土地タイプ（平地・島・沼・山・森） | E38: Basic land types | F38: 305.6 | G38: 平地・島・沼・山・森の5種。対応する色のマナを出す能力を自動で持ち、土地渡りなど多くのカードが参照する。 | H38: アルファ (1993) | I38: 5属性に対応する資源タイプにする。各属性の資源から対応する属性のエネルギーが出る形にすれば、多色デッキの資源配分が構築の悩みどころになる。 | J38: 中 | K38: 色・属性システム | L38: × | M38: 色・土地前提
... A50: 49 | B50: サブタイプ | C50: ドロー・手札 | D50: 講義 | E50: Lesson | F50: 205.3k | G50: ストリクスヘイヴンの呪文タイプ。履修などでサイドボードから講義カードを手札に加えられる。 | H50: ストリクスヘイヴン：魔法学院 (2021) | I50: デッキ外の控えカードから状況に応じて1枚を手札に呼び込む。控え枠を5枚程度に固定し、呼び込む効果にポイントを割り当てると構築の幅が広がる。 | J50: 中 | K50: サイドボード枠 | L50: × | M50: サイドボード前提
A51: 50 | B51: サブタイプ | C51: その他 | D51: 合唱 | E51: Chorus | G51: MTGアリーナ限定の呪文タイプ。総合ルールにはなく、合唱を参照するデジタル専用カードと組む。 | H51: アルケミー：イクサラン (2023) | I51: デジタル専用カードの分類タグの例。紙では難しい効果（無作為生成や恒久強化）を持つカードを1つのタグにまとめ、そのタグを数えるカードで統一感を出す。 | J51: 高 | K51: タグシステム | L51: × | M51: デジタル分類タグのみ
A52: 51 | B52: サブタイプ | C52: 攻撃 | D52: 包囲戦 | E52: Siege | F52: 205.3q | G52: バトル・タイプ。対戦相手を守る者に選んで戦場に出し、守備カウンターを全て取り除くと追放して変身面を無料で唱えられる。 | H52: 機械兵団の進軍 (2023) | I52: 相手側に置く攻略目標で、撃破すると裏面の強力なユニットや効果が手に入る。撃破に必要なダメージと報酬の大きさから逆算してポイントを決める。 | J52: 中 | K52: 攻撃先選択 | L52: △ | M52: No.2と同じ。相手側の攻略目標は新ゾーンが要る
A53: 52 | B53: サブタイプ | C53: デッキ構築 | D53: プレインズウォーカー・タイプ | E53: Planeswalker types | F53: 205.3j | G53: ジェイスやチャンドラなど人物名がサブタイプになる。かつては同タイプのPWを1体しか持てないルールがあった。 | H53: ローウィン (2007) | I53: 人物名をタグにして同じ人物のカードを参照させる。同じ人物は場に1枚までとすれば、人物の差し替えによる立て直しが戦略になる。 | J53: 高 | K53: タグシステム | L53: × | M53: 人物タグ前提
A54: 53 | B54: サブタイプ | C54: デッキ構築 | D54: クリーチャー・タイプ（部族シナジー） | E54: Creature types | F54: 205.3m | G54: エルフやゴブリンなど種族・職業を表す300種以上のサブタイプ。同タイプを強化するロードや部族カードがデッキの軸になる。 | H54: アルファ (1993) | I54: 種族タグを5〜8種に絞り、各種族に「同種族1体ごとに強化」や「同種族をサーチ」を配る。種族数が多すぎると構築が分散するので、最初は少数で始め拡張時に追加する。 | J54: 高 | K54: タグシステム | L54: ◎ | M54: 【今回実装：種族タグ＋条件『同じ種族の自分のモンスターがいる』・修飾『同じ種族1体につき』・対象『同じ種族の自分のモンスター全体』（`tribe`・バッチC2）】（審査時は○）種族タグ（5〜8種）＋条件『同種族が2体以上』・効果『同種族1体ごとに攻撃力+N』。タグ機構が要る
A55: 54 | B55: カードレイアウト | C55: その他 | D55: 分割カード | E55: Split card | F55: 709 | G55: 1枚に小さな呪文2つを並べ、唱える時にどちらか一方を選ぶ。手札や墓地では両半分の特性を併せ持つものとして扱う。 | H55: インベイジョン (2000) | I55: 1枚に軽い効果Aと重い効果Bを載せ、使う時にどちらかを選ぶ。ポイントは両方の合計より割安にし、状況対応力そのものに値段を付ける。UIは左右タップで選択。 | J55: 高 | K55: なし | L55: ◎ | M55: 【今回実装：モード選択（次のうち1つを選ぶ）（`modes`・バッチC2）】（審査時は○）選択式カード：効果A/Bを使用時に選ぶ。ポイントは高い方＋低い方の3割
A56: 55 | B56: カードレイアウト | C56: コスト・リソース | D56: 部屋 | E56: Room | F56: 709 | G56: 2つの扉を持つ分割エンチャント。片方の扉だけ開けた状態で出し、後からコストを払って残りの扉を開けると追加の効果が働く。 | H56: ダスクモーン：戦慄の館 (2024) | I56: 設置型カードに第2の扉を用意し、後でエネルギーを払って開けると別効果が起動する。1枚が中長期の投資先になり、ポイントは扉ごとに個別に計上できる。 | J56: 中 | K56: 場に残るカード | L56: × | M56: 扉の開閉が重い。パワーで代用可
A57: 56 | B57: カードレイアウト | C57: 条件ボーナス | D57: 反転カード | E57: Flip card | F57: 710 | G57: 上下逆さにもう一つの特性を印刷し、条件を満たすと戦場のパーマネントを反転させて強化版に切り替える。元には戻らない。 | H57: 神河物語 (2004) | I57: 条件達成で上位形態に変わる一方通行の進化カード。デジタルなら演出付きで切り替えを見せられ、条件の難しさに応じて変化後ステータスのポイントを割り引ける。 | J57: 中 | K57: 場に残るカード | L57: △ | M57: 条件達成でモンスターが強化版に変わる『進化』。変身データが要る
A58: 57 | B58: カードレイアウト | C58: 条件ボーナス | D58: 変身する両面カード | E58: Transforming double-faced card | F58: 712 | G58: 表裏の両面に別々の特性を持ち、効果によって裏返る。人狼のように条件次第で何度も表裏を行き来するものもある。 | H58: イニストラード (2011) | I58: 表裏で別性能のカードを作り、条件で何度でも切り替え可能にする。裏面を常時プレビューできるUIで情報差を減らす。状態を持つぶんポイント上限を高めに設定する。 | J58: 中 | K58: 状態フラグ | L58: △ | M58: No.56と統合。何度も表裏は不要
A59: 58 | B59: カードレイアウト | C59: コスト・リソース | D59: モードを持つ両面カード | E59: Modal double-faced card (MDFC) | F59: 712 | G59: 手札から出すときにどちらの面としてプレイするかを選ぶ両面カード。片面が土地のものが多く、マナ事故の緩和に役立つ。 | H59: ゼンディカーの夜明け (2020) | I59: 表は攻撃カード、裏はエネルギー供給カードのように、使うときに面を選べる。手札事故を減らす救済枠として、片面ずつのポイントをやや低めに設定する。 | J59: 高 | K59: なし | L59: × | M59: No.54の選択式カードで十分
A60: 59 | B60: カードレイアウト | C60: 強化 | D60: 合体 | E60: Meld | F60: 701.42 | G60: 対になる特定の2枚を両方コントロールし条件を満たすと、2枚が1体の巨大なパーマネントに合わさる。 | H60: 異界月 (2016) | I60: 対になる2枚を場に揃え条件を満たすと合体ユニットに変わる。デッキに組み込む難度が高いぶん、合体後のポイントを2枚分以上にしてロマン枠にする。 | J60: 中 | K60: 場に残るカード | L60: × | M60: 2枚合体は重くロマン枠
A61: 60 | B61: カードレイアウト | C61: 反復・再利用 | D61: 出来事 | E61: Adventure | F61: 715 | G61: クリーチャーに小さな呪文が付属し、先に呪文として使うと追放され、後でその追放領域からクリーチャー本体を唱えられる。 | H61: エルドレインの王権 (2019) | I61: 1枚に先に使う小技と後で出す本体を持たせ、小技使用後は専用の待機ゾーンへ置く。1枚で2回行動できるため、ポイントは単体カードより割高に設定する。 | J61: 中 | K61: 待機ゾーン | L61: △ | M61: 小技を使った後に本体を出す待機ゾーンが要る。後回し
A62: 61 | B62: カードレイアウト | C62: 山札操作 | D62: 前兆 | E62: Omen | F62: 720 | G62: クリーチャーに付属する前兆呪文として唱えると、解決後に墓地でなくライブラリーに切り直される。後で本体として引き直せる。 | H62: タルキール：龍嵐録 (2025) | I62: 呪文面で使うと捨て札ではなく山札にシャッフルされる。リソースが山札に戻るので長期戦向け。StS型の山札循環と相性がよく、前兆面のポイントを安くできる。 | J62: 高 | K62: 山札シャッフル | L62: ◎ | M62: 【今回実装：カードの能力『循環』（`shuffleBack`・バッチB）】（審査時は○）修飾『循環』：使った後に捨て札でなく山札に混ぜる。+1pt 程度
...

Sheet 集計
A1: 大分類 × 導入しやすさ
A3: 大分類 | B3: 件数 | C3: 導入しやすさ 高 | D3: 中 | E3: 低 | F3: 採用検討 ◎ | G3: ○ | H3: △ | I3: × | J3: 未検討
A4: カードタイプ | B4: =COUNTIF(全要素一覧!$B$2:$B$642,A4) | C4: =COUNTIFS(全要素一覧!$B$2:$B$642,$A4,全要素一覧!$J$2:$J$642,"高") | D4: =COUNTIFS(全要素一覧!$B$2:$B$642,$A4,全要素一覧!$J$2:$J$642,"中") | E4: =COUNTIFS(全要素一覧!$B$2:$B$642,$A4,全要素一覧!$J$2:$J$642,"低") | F4: =COUNTIFS(全要素一覧!$B$2:$B$642,$A4,全要素一覧!$L$2:$L$642,"◎") | G4: =COUNTIFS(全要素一覧!$B$2:$B$642,$A4,全要素一覧!$L$2:$L$642,"○") | H4: =COUNTIFS(全要素一覧!$B$2:$B$642,$A4,全要素一覧!$L$2:$L$642,"△") | I4: =COUNTIFS(全要素一覧!$B$2:$B$642,$A4,全要素一覧!$L$2:$L$642,"×") | J4: =B4-SUM(F4:I4)
A5: 特殊タイプ | B5: =COUNTIF(全要素一覧!$B$2:$B$642,A5) | C5: =COUNTIFS(全要素一覧!$B$2:$B$642,$A5,全要素一覧!$J$2:$J$642,"高") | D5: =COUNTIFS(全要素一覧!$B$2:$B$642,$A5,全要素一覧!$J$2:$J$642,"中") | E5: =COUNTIFS(全要素一覧!$B$2:$B$642,$A5,全要素一覧!$J$2:$J$642,"低") | F5: =COUNTIFS(全要素一覧!$B$2:$B$642,$A5,全要素一覧!$L$2:$L$642,"◎") | G5: =COUNTIFS(全要素一覧!$B$2:$B$642,$A5,全要素一覧!$L$2:$L$642,"○") | H5: =COUNTIFS(全要素一覧!$B$2:$B$642,$A5,全要素一覧!$L$2:$L$642,"△") | I5: =COUNTIFS(全要素一覧!$B$2:$B$642,$A5,全要素一覧!$L$2:$L$642,"×") | J5: =B5-SUM(F5:I5)
A6: サブタイプ | B6: =COUNTIF(全要素一覧!$B$2:$B$642,A6) | C6: =COUNTIFS(全要素一覧!$B$2:$B$642,$A6,全要素一覧!$J$2:$J$642,"高") | D6: =COUNTIFS(全要素一覧!$B$2:$B$642,$A6,全要素一覧!$J$2:$J$642,"中") | E6: =COUNTIFS(全要素一覧!$B$2:$B$642,$A6,全要素一覧!$J$2:$J$642,"低") | F6: =COUNTIFS(全要素一覧!$B$2:$B$642,$A6,全要素一覧!$L$2:$L$642,"◎") | G6: =COUNTIFS(全要素一覧!$B$2:$B$642,$A6,全要素一覧!$L$2:$L$642,"○") | H6: =COUNTIFS(全要素一覧!$B$2:$B$642,$A6,全要素一覧!$L$2:$L$642,"△") | I6: =COUNTIFS(全要素一覧!$B$2:$B$642,$A6,全要素一覧!$L$2:$L$642,"×") | J6: =B6-SUM(F6:I6)
A7: カードレイアウト | B7: =COUNTIF(全要素一覧!$B$2:$B$642,A7) | C7: =COUNTIFS(全要素一覧!$B$2:$B$642,$A7,全要素一覧!$J$2:$J$642,"高") | D7: =COUNTIFS(全要素一覧!$B$2:$B$642,$A7,全要素一覧!$J$2:$J$642,"中") | E7: =COUNTIFS(全要素一覧!$B$2:$B$642,$A7,全要素一覧!$J$2:$J$642,"低") | F7: =COUNTIFS(全要素一覧!$B$2:$B$642,$A7,全要素一覧!$L$2:$L$642,"◎") | G7: =COUNTIFS(全要素一覧!$B$2:$B$642,$A7,全要素一覧!$L$2:$L$642,"○") | H7: =COUNTIFS(全要素一覧!$B$2:$B$642,$A7,全要素一覧!$L$2:$L$642,"△") | I7: =COUNTIFS(全要素一覧!$B$2:$B$642,$A7,全要素一覧!$L$2:$L$642,"×") | J7: =B7-SUM(F7:I7)
A8: ゾーン | B8: =COUNTIF(全要素一覧!$B$2:$B$642,A8) | C8: =COUNTIFS(全要素一覧!$B$2:$B$642,$A8,全要素一覧!$J$2:$J$642,"高") | D8: =COUNTIFS(全要素一覧!$B$2:$B$642,$A8,全要素一覧!$J$2:$J$642,"中") | E8: =COUNTIFS(全要素一覧!$B$2:$B$642,$A8,全要素一覧!$J$2:$J$642,"低") | F8: =COUNTIFS(全要素一覧!$B$2:$B$642,$A8,全要素一覧!$L$2:$L$642,"◎") | G8: =COUNTIFS(全要素一覧!$B$2:$B$642,$A8,全要素一覧!$L$2:$L$642,"○") | H8: =COUNTIFS(全要素一覧!$B$2:$B$642,$A8,全要素一覧!$L$2:$L$642,"△") | I8: =COUNTIFS(全要素一覧!$B$2:$B$642,$A8,全要素一覧!$L$2:$L$642,"×") | J8: =B8-SUM(F8:I8)
A9: ターン構造 | B9: =COUNTIF(全要素一覧!$B$2:$B$642,A9) | C9: =COUNTIFS(全要素一覧!$B$2:$B$642,$A9,全要素一覧!$J$2:$J$642,"高") | D9: =COUNTIFS(全要素一覧!$B$2:$B$642,$A9,全要素一覧!$J$2:$J$642,"中") | E9: =COUNTIFS(全要素一覧!$B$2:$B$642,$A9,全要素一覧!$J$2:$J$642,"低") | F9: =COUNTIFS(全要素一覧!$B$2:$B$642,$A9,全要素一覧!$L$2:$L$642,"◎") | G9: =COUNTIFS(全要素一覧!$B$2:$B$642,$A9,全要素一覧!$L$2:$L$642,"○") | H9: =COUNTIFS(全要素一覧!$B$2:$B$642,$A9,全要素一覧!$L$2:$L$642,"△") | I9: =COUNTIFS(全要素一覧!$B$2:$B$642,$A9,全要素一覧!$L$2:$L$642,"×") | J9: =B9-SUM(F9:I9)
A10: ゲームシステム | B10: =COUNTIF(全要素一覧!$B$2:$B$642,A10) | C10: =COUNTIFS(全要素一覧!$B$2:$B$642,$A10,全要素一覧!$J$2:$J$642,"高") | D10: =COUNTIFS(全要素一覧!$B$2:$B$642,$A10,全要素一覧!$J$2:$J$642,"中") | E10: =COUNTIFS(全要素一覧!$B$2:$B$642,$A10,全要素一覧!$J$2:$J$642,"低") | F10: =COUNTIFS(全要素一覧!$B$2:$B$642,$A10,全要素一覧!$L$2:$L$642,"◎") | G10: =COUNTIFS(全要素一覧!$B$2:$B$642,$A10,全要素一覧!$L$2:$L$642,"○") | H10: =COUNTIFS(全要素一覧!$B$2:$B$642,$A10,全要素一覧!$L$2:$L$642,"△") | I10: =COUNTIFS(全要素一覧!$B$2:$B$642,$A10,全要素一覧!$L$2:$L$642,"×") | J10: =B10-SUM(F10:I10)
A11: カウンター | B11: =COUNTIF(全要素一覧!$B$2:$B$642,A11) | C11: =COUNTIFS(全要素一覧!$B$2:$B$642,$A11,全要素一覧!$J$2:$J$642,"高") | D11: =COUNTIFS(全要素一覧!$B$2:$B$642,$A11,全要素一覧!$J$2:$J$642,"中") | E11: =COUNTIFS(全要素一覧!$B$2:$B$642,$A11,全要素一覧!$J$2:$J$642,"低") | F11: =COUNTIFS(全要素一覧!$B$2:$B$642,$A11,全要素一覧!$L$2:$L$642,"◎") | G11: =COUNTIFS(全要素一覧!$B$2:$B$642,$A11,全要素一覧!$L$2:$L$642,"○") | H11: =COUNTIFS(全要素一覧!$B$2:$B$642,$A11,全要素一覧!$L$2:$L$642,"△") | I11: =COUNTIFS(全要素一覧!$B$2:$B$642,$A11,全要素一覧!$L$2:$L$642,"×") | J11: =B11-SUM(F11:I11)
A12: トークン | B12: =COUNTIF(全要素一覧!$B$2:$B$642,A12) | C12: =COUNTIFS(全要素一覧!$B$2:$B$642,$A12,全要素一覧!$J$2:$J$642,"高") | D12: =COUNTIFS(全要素一覧!$B$2:$B$642,$A12,全要素一覧!$J$2:$J$642,"中") | E12: =COUNTIFS(全要素一覧!$B$2:$B$642,$A12,全要素一覧!$J$2:$J$642,"低") | F12: =COUNTIFS(全要素一覧!$B$2:$B$642,$A12,全要素一覧!$L$2:$L$642,"◎") | G12: =COUNTIFS(全要素一覧!$B$2:$B$642,$A12,全要素一覧!$L$2:$L$642,"○") | H12: =COUNTIFS(全要素一覧!$B$2:$B$642,$A12,全要素一覧!$L$2:$L$642,"△") | I12: =COUNTIFS(全要素一覧!$B$2:$B$642,$A12,全要素一覧!$L$2:$L$642,"×") | J12: =B12-SUM(F12:I12)
A13: 指定・状態 | B13: =COUNTIF(全要素一覧!$B$2:$B$642,A13) | C13: =COUNTIFS(全要素一覧!$B$2:$B$642,$A13,全要素一覧!$J$2:$J$642,"高") | D13: =COUNTIFS(全要素一覧!$B$2:$B$642,$A13,全要素一覧!$J$2:$J$642,"中") | E13: =COUNTIFS(全要素一覧!$B$2:$B$642,$A13,全要素一覧!$J$2:$J$642,"低") | F13: =COUNTIFS(全要素一覧!$B$2:$B$642,$A13,全要素一覧!$L$2:$L$642,"◎") | G13: =COUNTIFS(全要素一覧!$B$2:$B$642,$A13,全要素一覧!$L$2:$L$642,"○") | H13: =COUNTIFS(全要素一覧!$B$2:$B$642,$A13,全要素一覧!$L$2:$L$642,"△") | I13: =COUNTIFS(全要素一覧!$B$2:$B$642,$A13,全要素一覧!$L$2:$L$642,"×") | J13: =B13-SUM(F13:I13)
A14: キーワード能力 | B14: =COUNTIF(全要素一覧!$B$2:$B$642,A14) | C14: =COUNTIFS(全要素一覧!$B$2:$B$642,$A14,全要素一覧!$J$2:$J$642,"高") | D14: =COUNTIFS(全要素一覧!$B$2:$B$642,$A14,全要素一覧!$J$2:$J$642,"中") | E14: =COUNTIFS(全要素一覧!$B$2:$B$642,$A14,全要素一覧!$J$2:$J$642,"低") | F14: =COUNTIFS(全要素一覧!$B$2:$B$642,$A14,全要素一覧!$L$2:$L$642,"◎") | G14: =COUNTIFS(全要素一覧!$B$2:$B$642,$A14,全要素一覧!$L$2:$L$642,"○") | H14: =COUNTIFS(全要素一覧!$B$2:$B$642,$A14,全要素一覧!$L$2:$L$642,"△") | I14: =COUNTIFS(全要素一覧!$B$2:$B$642,$A14,全要素一覧!$L$2:$L$642,"×") | J14: =B14-SUM(F14:I14)
A15: キーワード処理 | B15: =COUNTIF(全要素一覧!$B$2:$B$642,A15) | C15: =COUNTIFS(全要素一覧!$B$2:$B$642,$A15,全要素一覧!$J$2:$J$642,"高") | D15: =COUNTIFS(全要素一覧!$B$2:$B$642,$A15,全要素一覧!$J$2:$J$642,"中") | E15: =COUNTIFS(全要素一覧!$B$2:$B$642,$A15,全要素一覧!$J$2:$J$642,"低") | F15: =COUNTIFS(全要素一覧!$B$2:$B$642,$A15,全要素一覧!$L$2:$L$642,"◎") | G15: =COUNTIFS(全要素一覧!$B$2:$B$642,$A15,全要素一覧!$L$2:$L$642,"○") | H15: =COUNTIFS(全要素一覧!$B$2:$B$642,$A15,全要素一覧!$L$2:$L$642,"△") | I15: =COUNTIFS(全要素一覧!$B$2:$B$642,$A15,全要素一覧!$L$2:$L$642,"×") | J15: =B15-SUM(F15:I15)
... A19: デザイン手法 | B19: =COUNTIF(全要素一覧!$B$2:$B$642,A19) | C19: =COUNTIFS(全要素一覧!$B$2:$B$642,$A19,全要素一覧!$J$2:$J$642,"高") | D19: =COUNTIFS(全要素一覧!$B$2:$B$642,$A19,全要素一覧!$J$2:$J$642,"中") | E19: =COUNTIFS(全要素一覧!$B$2:$B$642,$A19,全要素一覧!$J$2:$J$642,"低") | F19: =COUNTIFS(全要素一覧!$B$2:$B$642,$A19,全要素一覧!$L$2:$L$642,"◎") | G19: =COUNTIFS(全要素一覧!$B$2:$B$642,$A19,全要素一覧!$L$2:$L$642,"○") | H19: =COUNTIFS(全要素一覧!$B$2:$B$642,$A19,全要素一覧!$L$2:$L$642,"△") | I19: =COUNTIFS(全要素一覧!$B$2:$B$642,$A19,全要素一覧!$L$2:$L$642,"×") | J19: =B19-SUM(F19:I19)
A20: 合計 | B20: =SUM(B4:B19) | C20: =SUM(C4:C19) | D20: =SUM(D4:D19) | E20: =SUM(E4:E19) | F20: =SUM(F4:F19) | G20: =SUM(G4:G19) | H20: =SUM(H4:H19) | I20: =SUM(I4:I19) | J20: =SUM(J4:J19)
A22: 機能タグ別の件数
A23: 機能タグ | B23: 件数 | C23: うち導入しやすさ 高
A24: 攻撃 | B24: =COUNTIF(全要素一覧!$C$2:$C$642,A24) | C24: =COUNTIFS(全要素一覧!$C$2:$C$642,A24,全要素一覧!$J$2:$J$642,"高")
A25: 回避 | B25: =COUNTIF(全要素一覧!$C$2:$C$642,A25) | C25: =COUNTIFS(全要素一覧!$C$2:$C$642,A25,全要素一覧!$J$2:$J$642,"高")
A26: 防御 | B26: =COUNTIF(全要素一覧!$C$2:$C$642,A26) | C26: =COUNTIFS(全要素一覧!$C$2:$C$642,A26,全要素一覧!$J$2:$J$642,"高")
A27: 除去 | B27: =COUNTIF(全要素一覧!$C$2:$C$642,A27) | C27: =COUNTIFS(全要素一覧!$C$2:$C$642,A27,全要素一覧!$J$2:$J$642,"高")
A28: 妨害 | B28: =COUNTIF(全要素一覧!$C$2:$C$642,A28) | C28: =COUNTIFS(全要素一覧!$C$2:$C$642,A28,全要素一覧!$J$2:$J$642,"高")
A29: ドロー・手札 | B29: =COUNTIF(全要素一覧!$C$2:$C$642,A29) | C29: =COUNTIFS(全要素一覧!$C$2:$C$642,A29,全要素一覧!$J$2:$J$642,"高")
A30: 山札操作 | B30: =COUNTIF(全要素一覧!$C$2:$C$642,A30) | C30: =COUNTIFS(全要素一覧!$C$2:$C$642,A30,全要素一覧!$J$2:$J$642,"高")
A31: 墓地利用 | B31: =COUNTIF(全要素一覧!$C$2:$C$642,A31) | C31: =COUNTIFS(全要素一覧!$C$2:$C$642,A31,全要素一覧!$J$2:$J$642,"高")
A32: コスト・リソース | B32: =COUNTIF(全要素一覧!$C$2:$C$642,A32) | C32: =COUNTIFS(全要素一覧!$C$2:$C$642,A32,全要素一覧!$J$2:$J$642,"高")
A33: 展開・トークン | B33: =COUNTIF(全要素一覧!$C$2:$C$642,A33) | C33: =COUNTIFS(全要素一覧!$C$2:$C$642,A33,全要素一覧!$J$2:$J$642,"高")
A34: 強化 | B34: =COUNTIF(全要素一覧!$C$2:$C$642,A34) | C34: =COUNTIFS(全要素一覧!$C$2:$C$642,A34,全要素一覧!$J$2:$J$642,"高")
A35: 成長・カウンター | B35: =COUNTIF(全要素一覧!$C$2:$C$642,A35) | C35: =COUNTIFS(全要素一覧!$C$2:$C$642,A35,全要素一覧!$J$2:$J$642,"高")
... A42: その他 | B42: =COUNTIF(全要素一覧!$C$2:$C$642,A42) | C42: =COUNTIFS(全要素一覧!$C$2:$C$642,A42,全要素一覧!$J$2:$J$642,"高")
